Workbook

Sheet field_dictionary
A1: id | B1: table_name | C1: field_name | D1: label | E1: BVD Codes (via vlookup) | F1: is code for [Business Term] > Name | G1: Definition (from Collibra) | H1: internal_description | I1: external_description | J1: data_type | K1: data_precision | L1: data_scale | M1: api_lineage | N1: is_primary_key | O1: foreign_keys | P1: created_at | Q1: last_updated | R1: is_deprecated | S1: business_owner | T1: security_classification | U1: update_frequency | V1: display_pattern | W1: allowed_values | X1: validation_rules | Y1: dq_metrics | Z1: path_depth | AA1: domain | AB1: reference_table
A2: 154 | B2: acnc | C2: bvd_id_number | D2: BvD_ID_number | E2: =VLOOKUP(B2&" - "&D2,OrbisGeneric_mapping!C:F,3,0) -> BVD_ID_NUMBER | F2: =VLOOKUP(E2,Collibra!D:F,3,0) -> BvD ID number | G2: =VLOOKUP(E2,Collibra!D:F,2,0) -> <p class="MsoNormal"><span style="font-size: 9.0pt;font-family: Arial , sans-serif;color: rgb(11,33,44);">The BvD ID number is a company identifier that uniquely identifies each company included in at least one Bureau van Dijk product. The first two characters correspond to the ISO country code (according the ISO 3166-1 alpha-2 standard) where the company is incorporated. The rest of a BvD ID number may vary and be based on a national ID, an information provider's ID, an own internal ID.</span> As a result, BvD ID numbers may be subject to change due to changes in national IDs or an information provider's ID.</p> | J2: STRING | N2: FALSE | P2: 2025-08-29T13:46:54.659Z | Q2: 2025-08-29T13:46:54.663Z | R2: FALSE | Z2: 1
A3: 250 | B3: acnc | C3: charity_beneficiaries | D3: Charity_beneficiaries | E3: =VLOOKUP(B3&" - "&D3,OrbisGeneric_mapping!C:F,3,0) -> CHARITY_BENEFICIARIES | F3: =VLOOKUP(E3,Collibra!D:F,3,0) -> Charity Beneficiaries | G3: =VLOOKUP(E3,Collibra!D:F,2,0) -> <p>Charities are able to nominate one or more beneficiaries from the list. If a charity has reported that they assist a beneficiary group, a ‘Y’ will be recorded in the column for the relevant beneficiary. Otherwise, the field will be blank.</p> <p>Possible beneficiaries are as follows: Aboriginal_or_TSI; Adults; Aged_Persons; Children; Communities_Overseas; Early_Childhood; Ethnic_Groups; Families; Females; Financially_Disadvantaged; Gay_Lesbian_Bisexual; General_Community_in_Australia; Males; Migrants_Refugees_or_Asylum_Seekers; Other_Beneficiaries; Other_Charities; People_at_risk_of_homelessness; People_with_Chronic_Illness; People_with_Disabilities; Pre_Post_Release_Offenders; Rural_Regional_Remote_Communities; Unemployed_Person; Veterans_or_their_families; Victims_of_crime; Victims_of_Disasters Youth</p> | J3: STRING | N3: FALSE | P3: 2025-08-29T13:46:54.659Z | Q3: 2025-08-29T13:46:54.663Z | R3: FALSE | Z3: 1
A4: 226 | B4: acnc | C4: charity_type | D4: Charity_type | E4: =VLOOKUP(B4&" - "&D4,OrbisGeneric_mapping!C:F,3,0) -> CHARITY_TYPE | F4: =VLOOKUP(E4,Collibra!D:F,3,0) -> Charity Type | G4: =VLOOKUP(E4,Collibra!D:F,2,0) -> Charities can be registered with one or more charity ‘subtypes’. These subtypes are categories that reflect the charity’s charitable purpose, for example ‘advancing education’ or ‘advancing health’. A charity’s purpose is the reason it has been set up, or what its activities work. | J4: STRING | N4: FALSE | P4: 2025-08-29T13:46:54.659Z | Q4: 2025-08-29T13:46:54.663Z | R4: FALSE | Z4: 1
A5: 234 | B5: acnc | C5: countries_of_operations | D5: Countries_of_operations | E5: =VLOOKUP(B5&" - "&D5,OrbisGeneric_mapping!C:F,3,0) -> CHARITY_OPERATING_COUNTRIES | F5: =VLOOKUP(E5,Collibra!D:F,3,0) -> Countries of operations | G5: =VLOOKUP(E5,Collibra!D:F,2,0) -> If the charity operates overseas, this column will contain data. The information in this field is based on the ISO 3166-1 alpha 3 codes. Where a charity operates in more than one overseas location, there will be multiple country codes. | J5: STRING | N5: FALSE | P5: 2025-08-29T13:46:54.659Z | Q5: 2025-08-29T13:46:54.663Z | R5: FALSE | Z5: 1
A6: 258 | B6: acnc | C6: date_established | D6: Date_established | E6: =VLOOKUP(B6&" - "&D6,OrbisGeneric_mapping!C:F,3,0) -> CHARITY_DATE_ORGANISATION_ESTABLISHED | F6: =VLOOKUP(E6,Collibra!D:F,3,0) -> Date Organisation Established | G6: =VLOOKUP(E6,Collibra!D:F,2,0) -> This field contains the date that the charity was established. Some organisations run as not-for-profits for years before deciding to register as charities. | J6: STRING | N6: FALSE | P6: 2025-08-29T13:46:54.659Z | Q6: 2025-08-29T13:46:54.663Z | R6: FALSE | Z6: 1
A7: 282 | B7: acnc | C7: date_established_day | D7: Date_established_day | E7: =VLOOKUP(B7&" - "&D7,OrbisGeneric_mapping!C:F,3,0) -> #N/A | F7: =VLOOKUP(E7,Collibra!D:F,3,0) -> #N/A | G7: =VLOOKUP(E7,Collibra!D:F,2,0) -> #N/A | J7: STRING | N7: FALSE | P7: 2025-08-29T13:46:54.659Z | Q7: 2025-08-29T13:46:54.663Z | R7: FALSE | Z7: 1
A8: 274 | B8: acnc | C8: date_established_month | D8: Date_established_month | E8: =VLOOKUP(B8&" - "&D8,OrbisGeneric_mapping!C:F,3,0) -> #N/A | F8: =VLOOKUP(E8,Collibra!D:F,3,0) -> #N/A | G8: =VLOOKUP(E8,Collibra!D:F,2,0) -> #N/A | J8: STRING | N8: FALSE | P8: 2025-08-29T13:46:54.659Z | Q8: 2025-08-29T13:46:54.663Z | R8: FALSE | Z8: 1
A9: 266 | B9: acnc | C9: date_established_year | D9: Date_established_year | E9: =VLOOKUP(B9&" - "&D9,OrbisGeneric_mapping!C:F,3,0) -> #N/A | F9: =VLOOKUP(E9,Collibra!D:F,3,0) -> #N/A | G9: =VLOOKUP(E9,Collibra!D:F,2,0) -> #N/A | J9: STRING | N9: FALSE | P9: 2025-08-29T13:46:54.659Z | Q9: 2025-08-29T13:46:54.663Z | R9: FALSE | Z9: 1
A10: 290 | B10: acnc | C10: last_delivery_date | D10: Last_delivery_date | E10: =VLOOKUP(B10&" - "&D10,OrbisGeneric_mapping!C:F,3,0) -> CHARITY_LAST_DELIVERY_DATE | F10: =VLOOKUP(E10,Collibra!D:F,3,0) -> Last delivery date | G10: =VLOOKUP(E10,Collibra!D:F,2,0) -> This field is populated with the most recent date on which we received Australian Charities and Not-for-profits Commission data, based on a record we keep of historical data received (DD/MM/YYYY). | J10: STRING | N10: FALSE | P10: 2025-08-29T13:46:54.659Z | Q10: 2025-08-29T13:46:54.663Z | R10: FALSE | Z10: 1
A11: 314 | B11: acnc | C11: last_delivery_date_day | D11: Last_delivery_date_day | E11: =VLOOKUP(B11&" - "&D11,OrbisGeneric_mapping!C:F,3,0) -> #N/A | F11: =VLOOKUP(E11,Collibra!D:F,3,0) -> #N/A | G11: =VLOOKUP(E11,Collibra!D:F,2,0) -> #N/A | J11: STRING | N11: FALSE | P11: 2025-08-29T13:46:54.659Z | Q11: 2025-08-29T13:46:54.663Z | R11: FALSE | Z11: 1
A12: 306 | B12: acnc | C12: last_delivery_date_month | D12: Last_delivery_date_month | E12: =VLOOKUP(B12&" - "&D12,OrbisGeneric_mapping!C:F,3,0) -> #N/A | F12: =VLOOKUP(E12,Collibra!D:F,3,0) -> #N/A | G12: =VLOOKUP(E12,Collibra!D:F,2,0) -> #N/A | J12: STRING | N12: FALSE | P12: 2025-08-29T13:46:54.659Z | Q12: 2025-08-29T13:46:54.663Z | R12: FALSE | Z12: 1
A13: 298 | B13: acnc | C13: last_delivery_date_year | D13: Last_delivery_date_year | E13: =VLOOKUP(B13&" - "&D13,OrbisGeneric_mapping!C:F,3,0) -> #N/A | F13: =VLOOKUP(E13,Collibra!D:F,3,0) -> #N/A | G13: =VLOOKUP(E13,Collibra!D:F,2,0) -> #N/A | J13: STRING | N13: FALSE | P13: 2025-08-29T13:46:54.659Z | Q13: 2025-08-29T13:46:54.663Z | R13: FALSE | Z13: 1
... A390: 1810 | B390: banks_global_financials_and_ratios | C390: unreserved_impaired_loans_equity_ | D390: Unreserved_impaired_loans_Equity_ | E390: =VLOOKUP(B390&" - "&D390,OrbisGeneric_mapping!C:F,3,0) -> 195070 | F390: =VLOOKUP(E390,Collibra!D:F,3,0) -> #N/A | G390: =VLOOKUP(E390,Collibra!D:F,2,0) -> #N/A | J390: STRING | N390: FALSE | P390: 2025-08-29T13:46:54.659Z | Q390: 2025-08-29T13:46:54.663Z | R390: FALSE | Z390: 1
A391: 1009 | B391: banks_global_financials_and_ratios_eur | C391: accounting_practice | D391: Accounting_practice | E391: =VLOOKUP(SUBSTITUTE(B391,"_eur","")&" - "&D391,OrbisGeneric_mapping!C:F,3,0) -> ACCOUNTING_PRACTICE | F391: =VLOOKUP(E391,Collibra!D:F,3,0) -> Accounting practice | G391: =VLOOKUP(E391,Collibra!D:F,2,0) -> <p>The accounting practice indicates the accounting standards based on which the financial accounts were prepared</p> <p>1. IFRS: IFRS (International Financial Reporting Standards) accounting practice is assigned to entities that follow accounting rules and standards issued by two standard-setting boards, the International Accounting Standards Board (IASB) and the newly created International Sustainability Standards Board. The IASB sets IFRS Accounting Standards and the ISSB sets IFRS Sustainability Disclosure Standards.</p> <p>2. IFRS – not fully complaint: IFRS – not fully complaint is assigned to entities that report financial statements based on IFRS accounting standards but has not adopted all IFRS accounting rules due to transition or exception to IFRS rule(s). </p> <p>3. Local GAAP: Local GAAP accounting practice is assigned to entities that follow the generally accepted accounting principles that are applicable in their respective jurisdictions where the company operates. E.g., Indian Accounting Standard (IND AS), Japanese GAAP</p> <p>4. US GAAP: US GAAP (United States Generally Accepted Accounting Principles) accounting practice is assigned to entities that follow the accounting rules and standards issued by the Financial Accounting Standards Board (FASB) for preparing its financial statements. </p> <p>5. Regulatory: No definition. Any local reporting should be Local GAAP.</p> | J391: STRING | N391: FALSE | P391: 2025-08-29T13:46:54.659Z | Q391: 2025-08-29T13:46:54.663Z | R391: FALSE | Z391: 1
A392: 1001 | B392: banks_global_financials_and_ratios_eur | C392: audit_status | D392: Audit_status | E392: =VLOOKUP(SUBSTITUTE(B392,"_eur","")&" - "&D392,OrbisGeneric_mapping!C:F,3,0) -> AUDIT_STATUS | F392: =VLOOKUP(E392,Collibra!D:F,3,0) -> Audit status | G392: =VLOOKUP(E392,Collibra!D:F,2,0) -> The audit status indicates the status of a statement with regard to its auditing. A financial accounts audit status could fall into qualified, unqualified, unaudited, adverse opinion, no opinion, qualification not available. This information is almost only available for publicy listed companies. | J392: STRING | N392: FALSE | P392: 2025-08-29T13:46:54.659Z | Q392: 2025-08-29T13:46:54.663Z | R392: FALSE | Z392: 1
A393: 945 | B393: banks_global_financials_and_ratios_eur | C393: bvd_id_number | D393: BvD_ID_number | E393: =VLOOKUP(SUBSTITUTE(B393,"_eur","")&" - "&D393,OrbisGeneric_mapping!C:F,3,0) -> BVD_ID_NUMBER | F393: =VLOOKUP(E393,Collibra!D:F,3,0) -> BvD ID number | G393: =VLOOKUP(E393,Collibra!D:F,2,0) -> <p class="MsoNormal"><span style="font-size: 9.0pt;font-family: Arial , sans-serif;color: rgb(11,33,44);">The BvD ID number is a company identifier that uniquely identifies each company included in at least one Bureau van Dijk product. The first two characters correspond to the ISO country code (according the ISO 3166-1 alpha-2 standard) where the company is incorporated. The rest of a BvD ID number may vary and be based on a national ID, an information provider's ID, an own internal ID.</span> As a result, BvD ID numbers may be subject to change due to changes in national IDs or an information provider's ID.</p> | J393: STRING | N393: FALSE | P393: 2025-08-29T13:46:54.659Z | Q393: 2025-08-29T13:46:54.663Z | R393: FALSE | Z393: 1
A394: 1585 | B394: banks_global_financials_and_ratios_eur | C394: cap_funds_dep_st_funding_ | D394: Cap_Funds_Dep_ST_Funding_ | E394: =VLOOKUP(SUBSTITUTE(B394,"_eur","")&" - "&D394,OrbisGeneric_mapping!C:F,3,0) -> 195160 | F394: =VLOOKUP(E394,Collibra!D:F,3,0) -> #N/A | G394: =VLOOKUP(E394,Collibra!D:F,2,0) -> #N/A | J394: STRING | N394: FALSE | P394: 2025-08-29T13:46:54.659Z | Q394: 2025-08-29T13:46:54.663Z | R394: FALSE | Z394: 1
A395: 1593 | B395: banks_global_financials_and_ratios_eur | C395: cap_funds_liabilities_ | D395: Cap_Funds_Liabilities_ | E395: =VLOOKUP(SUBSTITUTE(B395,"_eur","")&" - "&D395,OrbisGeneric_mapping!C:F,3,0) -> 195170 | F395: =VLOOKUP(E395,Collibra!D:F,3,0) -> #N/A | G395: =VLOOKUP(E395,Collibra!D:F,2,0) -> #N/A | J395: STRING | N395: FALSE | P395: 2025-08-29T13:46:54.659Z | Q395: 2025-08-29T13:46:54.663Z | R395: FALSE | Z395: 1
A396: 1577 | B396: banks_global_financials_and_ratios_eur | C396: cap_funds_net_loans_ | D396: Cap_Funds_Net_Loans_ | E396: =VLOOKUP(SUBSTITUTE(B396,"_eur","")&" - "&D396,OrbisGeneric_mapping!C:F,3,0) -> 195150 | F396: =VLOOKUP(E396,Collibra!D:F,3,0) -> #N/A | G396: =VLOOKUP(E396,Collibra!D:F,2,0) -> #N/A | J396: STRING | N396: FALSE | P396: 2025-08-29T13:46:54.659Z | Q396: 2025-08-29T13:46:54.663Z | R396: FALSE | Z396: 1
A397: 1569 | B397: banks_global_financials_and_ratios_eur | C397: cap_funds_total_assets_ | D397: Cap_Funds_Total_assets_ | E397: =VLOOKUP(SUBSTITUTE(B397,"_eur","")&" - "&D397,OrbisGeneric_mapping!C:F,3,0) -> 195140 | F397: =VLOOKUP(E397,Collibra!D:F,3,0) -> #N/A | G397: =VLOOKUP(E397,Collibra!D:F,2,0) -> #N/A | J397: STRING | N397: FALSE | P397: 2025-08-29T13:46:54.659Z | Q397: 2025-08-29T13:46:54.663Z | R397: FALSE | Z397: 1
A398: 961 | B398: banks_global_financials_and_ratios_eur | C398: closing_date | D398: Closing_date | E398: =VLOOKUP(SUBSTITUTE(B398,"_eur","")&" - "&D398,OrbisGeneric_mapping!C:F,3,0) -> CLOSING_DATE | F398: =VLOOKUP(E398,Collibra!D:F,3,0) -> Closing date | G398: =VLOOKUP(E398,Collibra!D:F,2,0) -> Closing date provides the financial accounts year or interim ending date (Default: Latest available year) | J398: STRING | N398: FALSE | P398: 2025-08-29T13:46:54.659Z | Q398: 2025-08-29T13:46:54.663Z | R398: FALSE | Z398: 1
A399: 985 | B399: banks_global_financials_and_ratios_eur | C399: closing_date_day | D399: Closing_date_day | E399: =VLOOKUP(SUBSTITUTE(B399,"_eur","")&" - "&D399,OrbisGeneric_mapping!C:F,3,0) -> #N/A | F399: =VLOOKUP(E399,Collibra!D:F,3,0) -> #N/A | G399: =VLOOKUP(E399,Collibra!D:F,2,0) -> #N/A | J399: STRING | N399: FALSE | P399: 2025-08-29T13:46:54.659Z | Q399: 2025-08-29T13:46:54.663Z | R399: FALSE | Z399: 1
A400: 977 | B400: banks_global_financials_and_ratios_eur | C400: closing_date_month | D400: Closing_date_month | E400: =VLOOKUP(SUBSTITUTE(B400,"_eur","")&" - "&D400,OrbisGeneric_mapping!C:F,3,0) -> #N/A | F400: =VLOOKUP(E400,Collibra!D:F,3,0) -> #N/A | G400: =VLOOKUP(E400,Collibra!D:F,2,0) -> #N/A | J400: STRING | N400: FALSE | P400: 2025-08-29T13:46:54.659Z | Q400: 2025-08-29T13:46:54.663Z | R400: FALSE | Z400: 1
A401: 969 | B401: banks_global_financials_and_ratios_eur | C401: closing_date_year | D401: Closing_date_year | E401: =VLOOKUP(SUBSTITUTE(B401,"_eur","")&" - "&D401,OrbisGeneric_mapping!C:F,3,0) -> #N/A | F401: =VLOOKUP(E401,Collibra!D:F,3,0) -> #N/A | G401: =VLOOKUP(E401,Collibra!D:F,2,0) -> #N/A | J401: STRING | N401: FALSE | P401: 2025-08-29T13:46:54.659Z | Q401: 2025-08-29T13:46:54.663Z | R401: FALSE | Z401: 1
A402: 953 | B402: banks_global_financials_and_ratios_eur | C402: consolidation_code | D402: Consolidation_code | E402: =VLOOKUP(SUBSTITUTE(B402,"_eur","")&" - "&D402,OrbisGeneric_mapping!C:F,3,0) -> CONSOLIDATION_CODE | F402: =VLOOKUP(E402,Collibra!D:F,3,0) -> Consolidation code | G402: =VLOOKUP(E402,Collibra!D:F,2,0) -> <p>Consolidation code defines whether a financial statement is Consolidated or Unconsolidated. Based on the number of financials statements published in a report, a numeric suffix is added (C1, C2, U1 and U2) to distinguish the reports available between various entities. Suffix 1 refers the entity publishes consolidated/unconsolidated only while suffix 2 represents the entity publishes both Consolidated and Unconsolidated in the same report. Similarly, to distinguish availability of additional consolidated or unconsolidated statement suffix * is added (C* and U*). Additional financial statements appears if the entity has different accounting standard or more than one source.</p> <p>Companies with limited financial data are those with a consolidation code of LF (limited financials). The information available for such companies is often based on rounded figures - or class level - officially available (sometimes also collected from other directories or web sites). In most cases only “Number of employees” and “Operating Revenue” are available. There are several countries where detailed financials are not available for some companies. In such cases, LF are quite often made of median value of revenue range (or estimate), median value of employee range (or estimate) and current capital. Figures are reported for the current year (when recently collected and reflecting latest situation) such as YYYY. Figures might change during the course of Year YYYY until 31/12/YYYY when they are fixed and new figures are reported for Year YYYY+1.</p> | J402: STRING | N402: FALSE | P402: 2025-08-29T13:46:54.659Z | Q402: 2025-08-29T13:46:54.663Z | R402: FALSE | Z402: 1
... A508: 1505 | B508: banks_global_financials_and_ratios_eur | C508: unreserved_impaired_loans_equity_ | D508: Unreserved_impaired_loans_Equity_ | E508: =VLOOKUP(SUBSTITUTE(B508,"_eur","")&" - "&D508,OrbisGeneric_mapping!C:F,3,0) -> 195070 | F508: =VLOOKUP(E508,Collibra!D:F,3,0) -> #N/A | G508: =VLOOKUP(E508,Collibra!D:F,2,0) -> #N/A | J508: STRING | N508: FALSE | P508: 2025-08-29T13:46:54.659Z | Q508: 2025-08-29T13:46:54.663Z | R508: FALSE | Z508: 1
A509: 2633 | B509: banks_global_financials_and_ratios_eur_interim | C509: accounting_practice | D509: Accounting_practice | E509: =VLOOKUP(B509&" - "&D509,OrbisGeneric_mapping!C:F,3,0) -> ACCOUNTING_PRACTICE | F509: =VLOOKUP(E509,Collibra!D:F,3,0) -> Accounting practice | G509: =VLOOKUP(E509,Collibra!D:F,2,0) -> <p>The accounting practice indicates the accounting standards based on which the financial accounts were prepared</p> <p>1. IFRS: IFRS (International Financial Reporting Standards) accounting practice is assigned to entities that follow accounting rules and standards issued by two standard-setting boards, the International Accounting Standards Board (IASB) and the newly created International Sustainability Standards Board. The IASB sets IFRS Accounting Standards and the ISSB sets IFRS Sustainability Disclosure Standards.</p> <p>2. IFRS – not fully complaint: IFRS – not fully complaint is assigned to entities that report financial statements based on IFRS accounting standards but has not adopted all IFRS accounting rules due to transition or exception to IFRS rule(s). </p> <p>3. Local GAAP: Local GAAP accounting practice is assigned to entities that follow the generally accepted accounting principles that are applicable in their respective jurisdictions where the company operates. E.g., Indian Accounting Standard (IND AS), Japanese GAAP</p> <p>4. US GAAP: US GAAP (United States Generally Accepted Accounting Principles) accounting practice is assigned to entities that follow the accounting rules and standards issued by the Financial Accounting Standards Board (FASB) for preparing its financial statements. </p> <p>5. Regulatory: No definition. Any local reporting should be Local GAAP.</p> | J509: STRING | N509: FALSE | P509: 2025-08-29T13:46:54.659Z | Q509: 2025-08-29T13:46:54.663Z | R509: FALSE | Z509: 1
A510: 2625 | B510: banks_global_financials_and_ratios_eur_interim | C510: audit_status | D510: Audit_status | E510: =VLOOKUP(B510&" - "&D510,OrbisGeneric_mapping!C:F,3,0) -> AUDIT_STATUS | F510: =VLOOKUP(E510,Collibra!D:F,3,0) -> Audit status | G510: =VLOOKUP(E510,Collibra!D:F,2,0) -> The audit status indicates the status of a statement with regard to its auditing. A financial accounts audit status could fall into qualified, unqualified, unaudited, adverse opinion, no opinion, qualification not available. This information is almost only available for publicy listed companies. | J510: STRING | N510: FALSE | P510: 2025-08-29T13:46:54.659Z | Q510: 2025-08-29T13:46:54.663Z | R510: FALSE | Z510: 1
A511: 2569 | B511: banks_global_financials_and_ratios_eur_interim | C511: bvd_id_number | D511: BvD_ID_number | E511: =VLOOKUP(B511&" - "&D511,OrbisGeneric_mapping!C:F,3,0) -> BVD_ID_NUMBER | F511: =VLOOKUP(E511,Collibra!D:F,3,0) -> BvD ID number | G511: =VLOOKUP(E511,Collibra!D:F,2,0) -> <p class="MsoNormal"><span style="font-size: 9.0pt;font-family: Arial , sans-serif;color: rgb(11,33,44);">The BvD ID number is a company identifier that uniquely identifies each company included in at least one Bureau van Dijk product. The first two characters correspond to the ISO country code (according the ISO 3166-1 alpha-2 standard) where the company is incorporated. The rest of a BvD ID number may vary and be based on a national ID, an information provider's ID, an own internal ID.</span> As a result, BvD ID numbers may be subject to change due to changes in national IDs or an information provider's ID.</p> | J511: STRING | N511: FALSE | P511: 2025-08-29T13:46:54.659Z | Q511: 2025-08-29T13:46:54.663Z | R511: FALSE | Z511: 1
A512: 3209 | B512: banks_global_financials_and_ratios_eur_interim | C512: cap_funds_dep_st_funding_ | D512: Cap_Funds_Dep_ST_Funding_ | E512: =VLOOKUP(B512&" - "&D512,OrbisGeneric_mapping!C:F,3,0) -> 195160 | F512: =VLOOKUP(E512,Collibra!D:F,3,0) -> #N/A | G512: =VLOOKUP(E512,Collibra!D:F,2,0) -> #N/A | J512: STRING | N512: FALSE | P512: 2025-08-29T13:46:54.659Z | Q512: 2025-08-29T13:46:54.663Z | R512: FALSE | Z512: 1
A513: 3217 | B513: banks_global_financials_and_ratios_eur_interim | C513: cap_funds_liabilities_ | D513: Cap_Funds_Liabilities_ | E513: =VLOOKUP(B513&" - "&D513,OrbisGeneric_mapping!C:F,3,0) -> 195170 | F513: =VLOOKUP(E513,Collibra!D:F,3,0) -> #N/A | G513: =VLOOKUP(E513,Collibra!D:F,2,0) -> #N/A | J513: STRING | N513: FALSE | P513: 2025-08-29T13:46:54.659Z | Q513: 2025-08-29T13:46:54.663Z | R513: FALSE | Z513: 1
A514: 3201 | B514: banks_global_financials_and_ratios_eur_interim | C514: cap_funds_net_loans_ | D514: Cap_Funds_Net_Loans_ | E514: =VLOOKUP(B514&" - "&D514,OrbisGeneric_mapping!C:F,3,0) -> 195150 | F514: =VLOOKUP(E514,Collibra!D:F,3,0) -> #N/A | G514: =VLOOKUP(E514,Collibra!D:F,2,0) -> #N/A | J514: STRING | N514: FALSE | P514: 2025-08-29T13:46:54.659Z | Q514: 2025-08-29T13:46:54.663Z | R514: FALSE | Z514: 1
A515: 3193 | B515: banks_global_financials_and_ratios_eur_interim | C515: cap_funds_total_assets_ | D515: Cap_Funds_Total_assets_ | E515: =VLOOKUP(B515&" - "&D515,OrbisGeneric_mapping!C:F,3,0) -> 195140 | F515: =VLOOKUP(E515,Collibra!D:F,3,0) -> #N/A | G515: =VLOOKUP(E515,Collibra!D:F,2,0) -> #N/A | J515: STRING | N515: FALSE | P515: 2025-08-29T13:46:54.659Z | Q515: 2025-08-29T13:46:54.663Z | R515: FALSE | Z515: 1
A516: 2585 | B516: banks_global_financials_and_ratios_eur_interim | C516: closing_date | D516: Closing_date | E516: =VLOOKUP(B516&" - "&D516,OrbisGeneric_mapping!C:F,3,0) -> CLOSING_DATE | F516: =VLOOKUP(E516,Collibra!D:F,3,0) -> Closing date | G516: =VLOOKUP(E516,Collibra!D:F,2,0) -> Closing date provides the financial accounts year or interim ending date (Default: Latest available year) | J516: STRING | N516: FALSE | P516: 2025-08-29T13:46:54.659Z | Q516: 2025-08-29T13:46:54.663Z | R516: FALSE | Z516: 1
A517: 2609 | B517: banks_global_financials_and_ratios_eur_interim | C517: closing_date_day | D517: Closing_date_day | E517: =VLOOKUP(B517&" - "&D517,OrbisGeneric_mapping!C:F,3,0) -> #N/A | F517: =VLOOKUP(E517,Collibra!D:F,3,0) -> #N/A | G517: =VLOOKUP(E517,Collibra!D:F,2,0) -> #N/A | J517: STRING | N517: FALSE | P517: 2025-08-29T13:46:54.659Z | Q517: 2025-08-29T13:46:54.663Z | R517: FALSE | Z517: 1
A518: 2601 | B518: banks_global_financials_and_ratios_eur_interim | C518: closing_date_month | D518: Closing_date_month | E518: =VLOOKUP(B518&" - "&D518,OrbisGeneric_mapping!C:F,3,0) -> #N/A | F518: =VLOOKUP(E518,Collibra!D:F,3,0) -> #N/A | G518: =VLOOKUP(E518,Collibra!D:F,2,0) -> #N/A | J518: STRING | N518: FALSE | P518: 2025-08-29T13:46:54.659Z | Q518: 2025-08-29T13:46:54.663Z | R518: FALSE | Z518: 1
A519: 2593 | B519: banks_global_financials_and_ratios_eur_interim | C519: closing_date_year | D519: Closing_date_year | E519: =VLOOKUP(B519&" - "&D519,OrbisGeneric_mapping!C:F,3,0) -> #N/A | F519: =VLOOKUP(E519,Collibra!D:F,3,0) -> #N/A | G519: =VLOOKUP(E519,Collibra!D:F,2,0) -> #N/A | J519: STRING | N519: FALSE | P519: 2025-08-29T13:46:54.659Z | Q519: 2025-08-29T13:46:54.663Z | R519: FALSE | Z519: 1
A520: 2577 | B520: banks_global_financials_and_ratios_eur_interim | C520: consolidation_code | D520: Consolidation_code | E520: =VLOOKUP(B520&" - "&D520,OrbisGeneric_mapping!C:F,3,0) -> CONSOLIDATION_CODE | F520: =VLOOKUP(E520,Collibra!D:F,3,0) -> Consolidation code | G520: =VLOOKUP(E520,Collibra!D:F,2,0) -> <p>Consolidation code defines whether a financial statement is Consolidated or Unconsolidated. Based on the number of financials statements published in a report, a numeric suffix is added (C1, C2, U1 and U2) to distinguish the reports available between various entities. Suffix 1 refers the entity publishes consolidated/unconsolidated only while suffix 2 represents the entity publishes both Consolidated and Unconsolidated in the same report. Similarly, to distinguish availability of additional consolidated or unconsolidated statement suffix * is added (C* and U*). Additional financial statements appears if the entity has different accounting standard or more than one source.</p> <p>Companies with limited financial data are those with a consolidation code of LF (limited financials). The information available for such companies is often based on rounded figures - or class level - officially available (sometimes also collected from other directories or web sites). In most cases only “Number of employees” and “Operating Revenue” are available. There are several countries where detailed financials are not available for some companies. In such cases, LF are quite often made of median value of revenue range (or estimate), median value of employee range (or estimate) and current capital. Figures are reported for the current year (when recently collected and reflecting latest situation) such as YYYY. Figures might change during the course of Year YYYY until 31/12/YYYY when they are fixed and new figures are reported for Year YYYY+1.</p> | J520: STRING | N520: FALSE | P520: 2025-08-29T13:46:54.659Z | Q520: 2025-08-29T13:46:54.663Z | R520: FALSE | Z520: 1
... A627: 3129 | B627: banks_global_financials_and_ratios_eur_interim | C627: unreserved_impaired_loans_equity_ | D627: Unreserved_impaired_loans_Equity_ | E627: =VLOOKUP(B627&" - "&D627,OrbisGeneric_mapping!C:F,3,0) -> 195070 | F627: =VLOOKUP(E627,Collibra!D:F,3,0) -> #N/A | G627: =VLOOKUP(E627,Collibra!D:F,2,0) -> #N/A | J627: STRING | N627: FALSE | P627: 2025-08-29T13:46:54.659Z | Q627: 2025-08-29T13:46:54.663Z | R627: FALSE | Z627: 1
...

Sheet OrbisGeneric_mapping
A1: Table name (raw) | B1: Table name | C1: Helper column | D1: Field name | E1: Bvd Codes | F1: cleansed field name
A2: Modelled_employee_sales_assets.txt | B2: =LEFT(A2,FIND(".txt",A2)-1) -> Modelled_employee_sales_assets | C2: =B2&" - "&F2 -> Modelled_employee_sales_assets - BvD_ID_number | D2: BvD ID number | E2: BVD_ID_NUMBER | F2: BvD_ID_number
A3: Modelled_employee_sales_assets.txt | B3: =LEFT(A3,FIND(".txt",A3)-1) -> Modelled_employee_sales_assets | C3: =B3&" - "&F3 -> Modelled_employee_sales_assets - Orbis_ID_number | D3: Orbis ID number | E3: ORBISID | F3: Orbis_ID_number
A4: Modelled_employee_sales_assets.txt | B4: =LEFT(A4,FIND(".txt",A4)-1) -> Modelled_employee_sales_assets | C4: =B4&" - "&F4 -> Modelled_employee_sales_assets - Model_data_Subject_corporate_group_linkage_description | D4: Model data - Subject corporate group linkage description | E4: SUBJECT_CORPORATE_GROUP_LINKAGE_DESCRIPTION | F4: Model_data_Subject_corporate_group_linkage_description
A5: Modelled_employee_sales_assets.txt | B5: =LEFT(A5,FIND(".txt",A5)-1) -> Modelled_employee_sales_assets | C5: =B5&" - "&F5 -> Modelled_employee_sales_assets - Model_data_Global_parent_bvdid | D5: Model data - Global parent bvdid | E5: MODEL_DATA_GLOBAL_PARENT_BVDID | F5: Model_data_Global_parent_bvdid
A6: Modelled_employee_sales_assets.txt | B6: =LEFT(A6,FIND(".txt",A6)-1) -> Modelled_employee_sales_assets | C6: =B6&" - "&F6 -> Modelled_employee_sales_assets - Model_data_Global_parent_operating_revenue_USD | D6: Model data - Global parent operating revenue USD | E6: MODEL_DATA_GLOBAL_PARENT_OPERATING_REVENUE | F6: Model_data_Global_parent_operating_revenue_USD
A7: Modelled_employee_sales_assets.txt | B7: =LEFT(A7,FIND(".txt",A7)-1) -> Modelled_employee_sales_assets | C7: =B7&" - "&F7 -> Modelled_employee_sales_assets - Model_data_Global_parent_operating_revenue_accuracy_indicator | D7: Model data - Global parent operating revenue accuracy indicator | E7: MODEL_DATA_GLOBAL_PARENT_OPERATING_REVENUE_ACCURACY_INDICATOR | F7: Model_data_Global_parent_operating_revenue_accuracy_indicator
A8: Modelled_employee_sales_assets.txt | B8: =LEFT(A8,FIND(".txt",A8)-1) -> Modelled_employee_sales_assets | C8: =B8&" - "&F8 -> Modelled_employee_sales_assets - Model_data_Global_parent_number_of_employees | D8: Model data - Global parent number of employees | E8: MODEL_DATA_GLOBAL_PARENT_NUMBER_OF_EMPLOYEES | F8: Model_data_Global_parent_number_of_employees
A9: Modelled_employee_sales_assets.txt | B9: =LEFT(A9,FIND(".txt",A9)-1) -> Modelled_employee_sales_assets | C9: =B9&" - "&F9 -> Modelled_employee_sales_assets - Model_data_Global_parent_number_of_employees_accuracy_indicator | D9: Model data - Global parent number of employees accuracy indicator | E9: MODEL_DATA_GLOBAL_PARENT_NUMBER_OF_EMPLOYEES_ACCURACY_INDICATOR | F9: Model_data_Global_parent_number_of_employees_accuracy_indicator
A10: Modelled_employee_sales_assets.txt | B10: =LEFT(A10,FIND(".txt",A10)-1) -> Modelled_employee_sales_assets | C10: =B10&" - "&F10 -> Modelled_employee_sales_assets - Model_data_Global_parent_total_assets | D10: Model data - Global parent total assets | E10: MODEL_DATA_GLOBAL_PARENT_TOTAL_ASSETS | F10: Model_data_Global_parent_total_assets
A11: Modelled_employee_sales_assets.txt | B11: =LEFT(A11,FIND(".txt",A11)-1) -> Modelled_employee_sales_assets | C11: =B11&" - "&F11 -> Modelled_employee_sales_assets - Model_data_Global_parent_total_assets_accuracy_indicator | D11: Model data - Global parent total assets accuracy indicator | E11: MODEL_DATA_GLOBAL_PARENT_TOTAL_ASSETS_ACCURACY_INDICATOR | F11: Model_data_Global_parent_total_assets_accuracy_indicator
A12: Modelled_employee_sales_assets.txt | B12: =LEFT(A12,FIND(".txt",A12)-1) -> Modelled_employee_sales_assets | C12: =B12&" - "&F12 -> Modelled_employee_sales_assets - Model_data_Calculation_date | D12: Model data - Calculation date | E12: MODEL_DATA_CALCULATION_DATE | F12: Model_data_Calculation_date
A13: Cyber_risk_rating_by_BitSight.txt | B13: =LEFT(A13,FIND(".txt",A13)-1) -> Cyber_risk_rating_by_BitSight | C13: =B13&" - "&F13 -> Cyber_risk_rating_by_BitSight - BvD_ID_number | D13: BvD ID number | E13: BVD_ID_NUMBER | F13: BvD_ID_number
... A336: Contact_info.txt (one line per company) | B336: =LEFT(A336,FIND(".txt",A336)-1) -> Contact_info | C336: =B336&" - "&F336 -> Contact_info - LONGITUDE | D336: LONGITUDE | E336: LONGITUDE | F336: LONGITUDE
A337: Contact_info.txt (one line per company) | B337: =LEFT(A337,FIND(".txt",A337)-1) -> Contact_info | C337: =B337&" - "&F337 -> Contact_info - Remarks_ | D337: Remarks: | F337: Remarks_
A338: Contact_info.txt (one line per company) | B338: =LEFT(A338,FIND(".txt",A338)-1) -> Contact_info | C338: =B338&" - "&F338 -> Contact_info - Priority_given_to_info_from_local_registry_filings | D338: Priority given to info from local registry filings | F338: Priority_given_to_info_from_local_registry_filings
A339: Contact_info.txt (one line per company) | B339: =LEFT(A339,FIND(".txt",A339)-1) -> Contact_info | C339: =B339&" - "&F339 -> Contact_info - Region_in_country_and_type_of_region_in_country_have_multiple_values_separated_by_a_pipe | D339: Region in country and type of region in country have multiple values separated by a pipe | F339: Region_in_country_and_type_of_region_in_country_have_multiple_values_separated_by_a_pipe
A340: All_addresses.txt (several lines per company) | B340: =LEFT(A340,FIND(".txt",A340)-1) -> All_addresses | C340: =B340&" - "&F340 -> All_addresses - BvD_ID_number | D340: BvD ID number | E340: BVD_ID_NUMBER | F340: BvD_ID_number
A341: All_addresses.txt (several lines per company) | B341: =LEFT(A341,FIND(".txt",A341)-1) -> All_addresses | C341: =B341&" - "&F341 -> All_addresses - Street_no_building_etc_line_1 | D341: Street, no., building etc, line 1 | E341: ADDRESS_LINE1_ADDITIONAL_INTERNATIONAL | F341: Street_no_building_etc_line_1
A342: All_addresses.txt (several lines per company) | B342: =LEFT(A342,FIND(".txt",A342)-1) -> All_addresses | C342: =B342&" - "&F342 -> All_addresses - Street_no_building_etc_line_1_native_ | D342: Street, no., building etc, line 1 (native) | E342: ADDRESS_LINE1_ADDITIONAL_LOCAL | F342: Street_no_building_etc_line_1_native_
A343: All_addresses.txt (several lines per company) | B343: =LEFT(A343,FIND(".txt",A343)-1) -> All_addresses | C343: =B343&" - "&F343 -> All_addresses - Street_no_building_etc_line_2 | D343: Street, no., building etc, line 2 | E343: ADDRESS_LINE2_ADDITIONAL_INTERNATIONAL | F343: Street_no_building_etc_line_2
A344: All_addresses.txt (several lines per company) | B344: =LEFT(A344,FIND(".txt",A344)-1) -> All_addresses | C344: =B344&" - "&F344 -> All_addresses - Street_no_building_etc_line_2_native_ | D344: Street, no., building etc, line 2 (native) | E344: ADDRESS_LINE2_ADDITIONAL_LOCAL | F344: Street_no_building_etc_line_2_native_
A345: All_addresses.txt (several lines per company) | B345: =LEFT(A345,FIND(".txt",A345)-1) -> All_addresses | C345: =B345&" - "&F345 -> All_addresses - Street_no_building_etc_line_3 | D345: Street, no., building etc, line 3 | E345: ADDRESS_LINE3_ADDITIONAL_INTERNATIONAL | F345: Street_no_building_etc_line_3
A346: All_addresses.txt (several lines per company) | B346: =LEFT(A346,FIND(".txt",A346)-1) -> All_addresses | C346: =B346&" - "&F346 -> All_addresses - Street_no_building_etc_line_3_native_ | D346: Street, no., building etc, line 3 (native) | E346: ADDRESS_LINE3_ADDITIONAL_LOCAL | F346: Street_no_building_etc_line_3_native_
A347: All_addresses.txt (several lines per company) | B347: =LEFT(A347,FIND(".txt",A347)-1) -> All_addresses | C347: =B347&" - "&F347 -> All_addresses - Street_no_building_etc_line_4 | D347: Street, no., building etc, line 4 | E347: ADDRESS_LINE4_ADDITIONAL_INTERNATIONAL | F347: Street_no_building_etc_line_4
A348: All_addresses.txt (several lines per company) | B348: =LEFT(A348,FIND(".txt",A348)-1) -> All_addresses | C348: =B348&" - "&F348 -> All_addresses - Street_no_building_etc_line_4_native_ | D348: Street, no., building etc, line 4 (native) | E348: ADDRESS_LINE4_ADDITIONAL_LOCAL | F348: Street_no_building_etc_line_4_native_
A349: All_addresses.txt (several lines per company) | B349: =LEFT(A349,FIND(".txt",A349)-1) -> All_addresses | C349: =B349&" - "&F349 -> All_addresses - Postcode | D349: Postcode | E349: POSTCODE_ADDITIONAL | F349: Postcode
A350: All_addresses.txt (several lines per company) | B350: =LEFT(A350,FIND(".txt",A350)-1) -> All_addresses | C350: =B350&" - "&F350 -> All_addresses - City | D350: City | E350: CITY_ADDITIONAL_INTERNATIONAL | F350: City
A351: All_addresses.txt (several lines per company) | B351: =LEFT(A351,FIND(".txt",A351)-1) -> All_addresses | C351: =B351&" - "&F351 -> All_addresses - City_native_ | D351: City (native) | E351: CITY_ADDITIONAL_LOCAL | F351: City_native_
... A483: Detailed_format_industries.txt | B483: =LEFT(A483,FIND(".txt",A483)-1) -> Detailed_format_industries | C483: =B483&" - "&F483 -> Detailed_format_industries - Exchange_rate_from_original_currency | D483: Exchange rate from original currency | E483: EXCHANGE_RATE | F483: Exchange_rate_from_original_currency
A484: Detailed_format_industries.txt | B484: =LEFT(A484,FIND(".txt",A484)-1) -> Detailed_format_industries | C484: =B484&" - "&F484 -> Detailed_format_industries - Total_Current_Assets | D484: Total Current Assets | E484: 13061 | F484: Total_Current_Assets
A485: Detailed_format_industries.txt | B485: =LEFT(A485,FIND(".txt",A485)-1) -> Detailed_format_industries | C485: =B485&" - "&F485 -> Detailed_format_industries - Net_Stated_Inventory | D485: Net Stated Inventory | E485: 20010 | F485: Net_Stated_Inventory
A486: Detailed_format_industries.txt | B486: =LEFT(A486,FIND(".txt",A486)-1) -> Detailed_format_industries | C486: =B486&" - "&F486 -> Detailed_format_industries - Raw_Materials | D486: Raw Materials | E486: 20015 | F486: Raw_Materials
A487: Detailed_format_industries.txt | B487: =LEFT(A487,FIND(".txt",A487)-1) -> Detailed_format_industries | C487: =B487&" - "&F487 -> Detailed_format_industries - Work_in_Progress | D487: Work in Progress | E487: 20020 | F487: Work_in_Progress
A488: Detailed_format_industries.txt | B488: =LEFT(A488,FIND(".txt",A488)-1) -> Detailed_format_industries | C488: =B488&" - "&F488 -> Detailed_format_industries - Finished_Goods | D488: Finished Goods | E488: 20025 | F488: Finished_Goods
A489: Detailed_format_industries.txt | B489: =LEFT(A489,FIND(".txt",A489)-1) -> Detailed_format_industries | C489: =B489&" - "&F489 -> Detailed_format_industries - Inventory_Prepayments | D489: Inventory Prepayments | E489: 20030 | F489: Inventory_Prepayments
A490: Detailed_format_industries.txt | B490: =LEFT(A490,FIND(".txt",A490)-1) -> Detailed_format_industries | C490: =B490&" - "&F490 -> Detailed_format_industries - Net_Accounts_Receivable | D490: Net Accounts Receivable | E490: 13052 | F490: Net_Accounts_Receivable
A491: Detailed_format_industries.txt | B491: =LEFT(A491,FIND(".txt",A491)-1) -> Detailed_format_industries | C491: =B491&" - "&F491 -> Detailed_format_industries - Accounts_Receivable | D491: Accounts Receivable | E491: 20040 | F491: Accounts_Receivable
A492: Detailed_format_industries.txt | B492: =LEFT(A492,FIND(".txt",A492)-1) -> Detailed_format_industries | C492: =B492&" - "&F492 -> Detailed_format_industries - Doubtful_Accounts | D492: Doubtful Accounts | E492: 20045 | F492: Doubtful_Accounts
A493: Detailed_format_industries.txt | B493: =LEFT(A493,FIND(".txt",A493)-1) -> Detailed_format_industries | C493: =B493&" - "&F493 -> Detailed_format_industries - Others_current_assets_ | D493: Others (current assets) | E493: 20050 | F493: Others_current_assets_
...

Sheet Collibra
A1: Level | B1: File Path | C1: Full Name | D1: Name | E1: Definition | F1: is code for [Business Term] > Name | G1: Technical Data Type | H1: Model ID | I1: Period Criteria | J1: Repetition Criteria | K1: governed by [Data Domain] > Name | L1: Status | M1: Request Code | N1: Supports MDM | O1: Where the field is accessible | P1: is part of [Code Set] > Name
A2: 4 | B2: \\Financial data\Detailed format\Corporate\Profit &amp; loss account | C2: 13000 | D2: 13000 | E2: Amount of total sales unadjusted for the costs related to generating them. It is calculated by adding all sales receipts before discounts, returns and allowances for the period | F2: Gross Sales | G2: MoneyValue | H2: IND | I2: NUMBER_QUARTERS | K2: Company Financials | L2: Active | M2: 313000 | P2: Orbis 4.1 Code Set
A3: 4 | B3: \\Financial data\Accounts header\Key financials &amp; employees\Global standard format\Detailed format\Corporate\Balance sheet\Profit &amp; loss account | C3: 13001 | D3: 13001 | E3: Sum of all the adjustments made to gross sales. It includes discounts, returns, allowances, commission, royalties, excise taxes, etc. | F3: Adjustments / Excise Tax | G3: MoneyValue | H3: IND | I3: NUMBER_YEARS | K3: Company Financials | L3: Active | M3: 313001 | P3: Orbis 4.1 Code Set
A4: 4 | C4: 13002 | D4: 13002 | E4: Amount of gross sales minus adjustments | F4: Net Sales | G4: MoneyValue | H4: IND | K4: Company Financials | L4: Active | M4: 313002 | P4: Orbis 4.1 Code Set
A5: 4 | C5: 13003 | D5: 13003 | E5: Revenue that the company derives from any source other than the sale of goods and services | F5: Other Revenues | G5: MoneyValue | H5: IND | K5: Company Financials | L5: Active | M5: 313003 | P5: Orbis 4.1 Code Set
A6: 4 | C6: 13004 | D6: 13004 | E6: Amount of income generated from the company's sale of goods and services as well as other sources of income from core business functions | F6: Total Revenues | G6: MoneyValue | H6: IND | K6: Company Financials | L6: Active | M6: 313004 | P6: Orbis 4.1 Code Set
A7: 4 | C7: 13018 | D7: 13018 | E7: Earnings before Interest, Tax and Depreciation and Amortization | F7: EBITDA | G7: MoneyValue | H7: IND | K7: Company Financials | L7: Active | M7: 313018 | P7: Orbis 4.1 Code Set
A8: 4 | B8: \\Financial data\Accounts header\Key financials &amp; employees\Global standard format\Detailed format\Corporate\Balance sheet\Profit &amp; loss account | C8: 13019 | D8: 13019 | E8: Portion of a fixed or tangible asset that has been considered consumed during the accounting period | F8: Depreciation | G8: MoneyValue | H8: IND | K8: Company Financials | L8: Active | M8: 313019 | P8: Orbis 4.1 Code Set
A9: 4 | B9: \\Financial data\Detailed format\Corporate\Profit &amp; loss account | C9: 13020 | D9: 13020 | E9: Amortization is the written-off amount of intangible assets over a specified time period. Depletion is the allocated cost of extracting natural resources, such as timber, minerals and oil from the earth | F9: Amortization & Depletion | G9: MoneyValue | H9: IND | I9: NUMBER_YEARS | K9: Company Financials | L9: Active | M9: 313020 | P9: Orbis 4.1 Code Set
A10: 4 | B10: \\Financial data\Detailed format\Corporate\Profit &amp; loss account | C10: 13021 | D10: 13021 | E10: Sum of depreciation, amortization &amp; depletion expenses | F10: Total depreciation, amortization & depletion | G10: MoneyValue | H10: IND | I10: NUMBER_QUARTERS | K10: Company Financials | L10: Active | M10: 313021 | P10: Orbis 4.1 Code Set
A11: 4 | C11: 13022 | D11: 13022 | E11: Amount of income realised from the company's business operations after deducting operating expenses such as cost of goods sold, wages, depreciation and amortization &amp; depletion | G11: MoneyValue | H11: IND | K11: Company Financials | L11: Active | M11: 313022 | P11: Orbis 4.1 Code Set
A12: 4 | B12: \\Financial data\Detailed format\Corporate\Profit &amp; loss account | C12: 13023 | D12: 13023 | E12: Amount of extraordinary pre-tax income and expenses that are infrequent and non-recurring in nature. This includes gains (losses) from disposal of assets, restructuring expenses, merger &amp; acquisition expenses, etc. | F12: Unusual / Exceptional Items | G12: MoneyValue | H12: IND | I12: NUMBER_QUARTERS | K12: Company Financials | L12: Active | M12: 313023 | P12: Orbis 4.1 Code Set
A13: 4 | B13: \\Financial data\Accounts header\Key financials &amp; employees\Global standard format\Detailed format\Banks\Corporate\Balance sheet\Profit &amp; loss account | C13: 13024 | D13: 13024 | E13: All operating revenues minus all operating expenses | F13: Earnings before Interest & Tax | G13: MoneyValue | H13: IND | I13: NUMBER_YEARS | K13: Company Financials | L13: Active | M13: 313024 | P13: Orbis 4.1 Code Set
A14: 4 | B14: \\Financial data\Accounts header\Key financials &amp; employees\Global standard format\Detailed format\Corporate\Balance sheet\Profit &amp; loss account | C14: 13025 | D14: 13025 | E14: Revenue generated from finance activities other than core business functions. It includes interest income, invesment income, income from derivatives, etc. | F14: Financial revenue | G14: MoneyValue | H14: IND | I14: NUMBER_YEARS | K14: Company Financials | L14: Active | M14: 313025 | P14: Orbis 4.1 Code Set
A15: 4 | C15: 13026 | D15: 13026 | E15: Expenditures incurred due to interests, fees and commissions on the company's borrowings from lenders and creditors. This includes expenses from deposit accounts held by the entity, borrowings, subordinated debt and other financial liabilities | G15: MoneyValue | H15: IND | K15: Company Financials | L15: Active | M15: 313026 | P15: Orbis 4.1 Code Set
A16: 4 | B16: \\Financial data\Detailed format\Corporate\Profit &amp; loss account | C16: 13027 | D16: 13027 | E16: Net amount from the income and expenses resulting from the company's financial activities | F16: Financial P/L | G16: MoneyValue | H16: IND | I16: NUMBER_YEARS | K16: Company Financials | L16: Active | M16: 313027 | P16: Orbis 4.1 Code Set
A17: 4 | B17: \\Financial data\Detailed format\Corporate\Profit &amp; loss account | C17: 13034 | D17: 13034 | E17: Company's profit, including all incomes and expenses except income tax expenses | G17: MoneyValue | H17: IND | K17: Company Financials | L17: Active | M17: 313034 | P17: Orbis 4.1 Code Set
A18: 4 | C18: 13035 | D18: 13035 | E18: Amount incurred by the company for the accounting period on its taxable profit | G18: MoneyValue | H18: IND | K18: Company Financials | L18: Active | M18: 313035 | P18: Orbis 4.1 Code Set
A19: 4 | C19: 13037 | D19: 13037 | E19: Company's profit after deducting income tax expense | G19: MoneyValue | H19: IND | K19: Company Financials | L19: Active | M19: 313037 | P19: Orbis 4.1 Code Set
A20: 4 | B20: \\Financial data\Detailed format\Corporate\Profit &amp; loss account | C20: 13038 | D20: 13038 | E20: Share of profit attributable to minority shareholders of the company | F20: Minority Interest | G20: MoneyValue | H20: IND | I20: NUMBER_QUARTERS | K20: Company Financials | L20: Active | M20: 313038 | P20: Orbis 4.1 Code Set
A21: 4 | C21: 13043 | D21: 13043 | E21: Amount of extraordinary after tax income and expenses from events that are unusual and infrequent in nature. It may include pre-acqusition profit, discontinued operations, sale of subsidiaries and joint ventures, etc. | G21: MoneyValue | H21: IND | K21: Company Financials | L21: Active | M21: 313043 | P21: Orbis 4.1 Code Set
A22: 4 | B22: \\Financial data\Accounts header\Key financials &amp; employees\Global standard format\Detailed format\Corporate\Balance sheet\Profit &amp; loss account | C22: 13044 | D22: 13044 | E22: Amount of dividends allocated/distributed to preferred shareholders. It is paid out of net income before dividends on common shares | F22: Preferred Dividends | G22: MoneyValue | H22: IND | I22: NUMBER_QUARTERS | K22: Company Financials | L22: Active | M22: 313044 | P22: Orbis 4.1 Code Set
A23: 4 | C23: 13045 | D23: 13045 | E23: Amount of profit (loss) after tax minus minority interests, other adjustments, extraordinary items after tax and preferred dividends | G23: MoneyValue | H23: IND | K23: Company Financials | L23: Active | M23: 313045 | P23: Orbis 4.1 Code Set
A24: 4 | C24: 13046 | D24: 13046 | E24: Amount of dividends allocated/distributed to common shareholders. It is the portion of earnings paid out to shareholders and not reinvested in the business | F24: Ordinary Dividends | G24: MoneyValue | H24: IND | K24: Company Financials | L24: Active | M24: 313046 | P24: Orbis 4.1 Code Set
A25: 4 | C25: 13047 | D25: 13047 | E25: Dividends to other than ordinary shareholders | F25: Dividend Share Capital Other | G25: MoneyValue | H25: IND | K25: Company Financials | L25: Active | M25: 313047 | P25: Orbis 4.1 Code Set
A26: 5 | B26: \\Financial data\Detailed format\Corporate\Balance sheet\Assets | C26: 13050 | D26: 13050 | E26: Value of company assets that are cash or can be converted into cash immediately. Cash equivalents include bank accounts and other short-term securities with maturities of less than 90 days | F26: Cash or Equivalent | G26: MoneyValue | H26: IND | I26: NUMBER_YEARS | K26: Company Financials | L26: Active | M26: 313050 | P26: Orbis 4.1 Code Set
A27: 5 | B27: \\Financial data\Detailed format\Corporate\Balance sheet\Assets | C27: 13051 | D27: 13051 | E27: Short-term investments also known as marketable securities can easily be converted to cash. It includes any investment instruments that will mature within one year or which are expected to be liquidated within one year. Some common examples may include CDs, money market accounts, treasury bills and government bonds maturing within one year | G27: MoneyValue | H27: IND | K27: Company Financials | L27: Active | M27: 313051 | P27: Orbis 4.1 Code Set
A28: 5 | B28: \\Financial data\Detailed format\Corporate\Balance sheet\Assets | C28: 13052 | D28: 13052 | E28: Gross amount of total money owed to a business by its customers minus allowances for doubtful accounts | F28: Net accounts receivable | G28: MoneyValue | H28: IND | I28: NUMBER_YEARS | K28: Company Financials | L28: Active | M28: 313052 | P28: Orbis 4.1 Code Set
A29: 5 | B29: \\Financial data\Accounts header\Key financials &amp; employees\Global standard format\Detailed format\Banks\Corporate\Balance sheet\Assets | C29: 13054 | D29: 13054 | E29: Amount of expenditures that have not yet been recorded by a company as an expense, but have been paid for in advance. They are initially recorded as assets, because the business will receive goods or services in the future | F29: Prepaid Expenses & Advances | G29: MoneyValue | H29: IND | I29: NUMBER_QUARTERS | K29: Company Financials | L29: Active | M29: 313054 | P29: Orbis 4.1 Code Set
A30: 5 | C30: 13061 | D30: 13061 | E30: Sum of all the assets that are expected to be conveniently sold, consumed, used or exhausted through general business operations within one year of the balance sheet date | G30: MoneyValue | H30: IND | K30: Company Financials | L30: Active | M30: 313061 | P30: Orbis 4.1 Code Set
A31: 5 | B31: \\Financial data\Accounts header\Key financials &amp; employees\Global standard format\Detailed format\Corporate\Balance sheet\Assets | C31: 13068 | D31: 13068 | E31: Value of all buildings, land, furniture, and other physical assets that a business has purchased to run its business. These are net of accumulated depreciation | F31: Net property, plant & equipment | G31: MoneyValue | H31: IND | I31: NUMBER_QUARTERS | K31: Company Financials | L31: Active | M31: 313068 | P31: Orbis 4.1 Code Set
A32: 5 | C32: 13070 | D32: 13070 | E32: Value of an intangible assets that is associated with purchase of one company by another. It is the portion of the purchase price that is higher than the sum of the net fair value of all of the assets purchased in the acquisitions. The value of brand name, customer base, good customer, employee relations and proprietary technology may represent goodwill | F32: Goodwill | G32: MoneyValue | H32: IND | K32: Company Financials | L32: Active | M32: 313070 | P32: Orbis 4.1 Code Set
A33: 5 | C33: 13071 | D33: 13071 | E33: Value of a non-physical assets other than goodwill. These assets may include intellectual property such as patents, trademarks and copyrights | G33: MoneyValue | H33: IND | K33: Company Financials | L33: Active | M33: 313071 | P33: Orbis 4.1 Code Set
A34: 5 | B34: \\Financial data\Accounts header\Key financials &amp; employees\Global standard format\Detailed format\Banks\Corporate\Balance sheet\Assets | C34: 13077 | D34: 13077 | E34: Sum of on-balance sheet assets | F34: Total assets | G34: MoneyValue | H34: IND | I34: NUMBER_YEARS | K34: Company Financials | L34: Active | M34: 313077 | P34: Orbis 4.1 Code Set
A35: 5 | C35: 14004 | D35: 14004 | E35: Portion of long-term debt due within one year | G35: MoneyValue | H35: IND | K35: Company Financials | L35: Active | M35: 314004 | P35: Orbis 4.1 Code Set
A36: 5 | C36: 14011 | D36: 14011 | E36: Sum of all short-term financial obligations due for settlement within one year of the balance sheet date (The sum of Loans, Trade creditors and Total other current liabilities) | G36: MoneyValue | H36: IND | K36: Company Financials | L36: Active | M36: 314011 | P36: Orbis 4.1 Code Set
A37: 5 | B37: \\Financial data\Accounts header\Key financials &amp; employees\Global standard format\Detailed format\Corporate\Balance sheet\Assets\Liabilities | C37: 14014 | D37: 14014 | E37: Payment obligations for leased assets | F37: Lease liabilities | G37: MoneyValue | H37: IND | I37: NUMBER_YEARS | K37: Company Financials | L37: Active | M37: 314014 | P37: Orbis 4.1 Code Set
A38: 5 | B38: \\Financial data\Detailed format\Corporate\Balance sheet\Liabilities | C38: 14016 | D38: 14016 | E38: Sum of all interest-bearing debt maturing in more than one year | F38: Total long-term interest-bearing debt | G38: MoneyValue | H38: IND | I38: NUMBER_QUARTERS | K38: Company Financials | L38: Active | M38: 314016 | P38: Orbis 4.1 Code Set
A39: 5 | C39: 14018 | D39: 14018 | E39: Minority ownership in other entities as part of liabilities | G39: MoneyValue | H39: IND | K39: Company Financials | L39: Active | M39: 314018 | P39: Orbis 4.1 Code Set
A40: 5 | B40: \\Financial data\Detailed format\Corporate\Balance sheet\Liabilities | C40: 14022 | D40: 14022 | E40: Sum of all liabilities | G40: MoneyValue | H40: IND | K40: Company Financials | L40: Active | M40: 314022 | P40: Orbis 4.1 Code Set
...
